FFFFFF.......FFF
======================================================================
FAIL: test_eval_1 (__main__.TestCollatz)
----------------------------------------------------------------------
Traceback (most recent call last):
  File "TestCollatz.py", line 54, in test_eval_1
    self.assertEqual(v, 20)
AssertionError: 1 != 20

======================================================================
FAIL: test_eval_2 (__main__.TestCollatz)
----------------------------------------------------------------------
Traceback (most recent call last):
  File "TestCollatz.py", line 58, in test_eval_2
    self.assertEqual(v, 125)
AssertionError: 1 != 125

======================================================================
FAIL: test_eval_3 (__main__.TestCollatz)
----------------------------------------------------------------------
Traceback (most recent call last):
  File "TestCollatz.py", line 62, in test_eval_3
    self.assertEqual(v, 89)
AssertionError: 1 != 89

======================================================================
FAIL: test_eval_4 (__main__.TestCollatz)
----------------------------------------------------------------------
Traceback (most recent call last):
  File "TestCollatz.py", line 66, in test_eval_4
    self.assertEqual(v, 174)
AssertionError: 1 != 174

======================================================================
FAIL: test_eval_5 (__main__.TestCollatz)
----------------------------------------------------------------------
Traceback (most recent call last):
  File "TestCollatz.py", line 70, in test_eval_5
    self.assertEqual(v, 209)
AssertionError: 1 != 209

======================================================================
FAIL: test_eval_6 (__main__.TestCollatz)
----------------------------------------------------------------------
Traceback (most recent call last):
  File "TestCollatz.py", line 74, in test_eval_6
    self.assertEqual(v, 262)
AssertionError: 1 != 262

======================================================================
FAIL: test_solve_1 (__main__.TestCollatz)
----------------------------------------------------------------------
Traceback (most recent call last):
  File "TestCollatz.py", line 108, in test_solve_1
    w.getvalue(), "1 10 20\n100 200 125\n201 210 89\n900 1000 174\n")
AssertionError: '1 10 1\n100 200 1\n201 210 1\n900 1000 1\n' != '1 10 20\n100 200 125\n201 210 89\n900 1000 174\n'
- 1 10 1
?      ^
+ 1 10 20
?      ^^
- 100 200 1
+ 100 200 125
?          ++
- 201 210 1
?         ^
+ 201 210 89
?         ^^
- 900 1000 1
+ 900 1000 174
?           ++


======================================================================
FAIL: test_solve_2 (__main__.TestCollatz)
----------------------------------------------------------------------
Traceback (most recent call last):
  File "TestCollatz.py", line 115, in test_solve_2
    w.getvalue(), "1 1 1\n999 1001 143\n657 10000 262\n")
AssertionError: '1 1 1\n999 1001 1\n657 10000 1\n' != '1 1 1\n999 1001 143\n657 10000 262\n'
  1 1 1
- 999 1001 1
+ 999 1001 143
?           ++
- 657 10000 1
?           ^
+ 657 10000 262
?           ^^^


======================================================================
FAIL: test_solve_3 (__main__.TestCollatz)
----------------------------------------------------------------------
Traceback (most recent call last):
  File "TestCollatz.py", line 122, in test_solve_3
    w.getvalue(), "1 10 351\n500 35 144\n1 999999 525\n")
AssertionError: '1 99999 1\n500 35 1\n1 999999 1\n' != '1 10 351\n500 35 144\n1 999999 525\n'
- 1 99999 1
+ 1 10 351
- 500 35 1
+ 500 35 144
?         ++
- 1 999999 1
?          ^
+ 1 999999 525
?          ^^^


----------------------------------------------------------------------
Ran 16 tests in 0.004s

FAILED (failures=9)
